Workbook

Sheet 00_Cover
A1: FINANCIAL FEASIBILITY & INVESTMENT DECISION MODEL
A2: FIN 545 · Workshop on Financial Modelling · Lovely Professional University
A4: Venture | B4: Campus Brew Café - a 30-seat café near LPU, Phagwara (GT Road)
A5: Investment question | B5: Does the café create enough value to justify the capital committed? Invest / Invest with Conditions / Do Not Invest
A6: Programme / Section | B6: M.Com
A7: Faculty | B7: Dr Basit
A8: Members / IDs | B8: Harleen
A9: Submission date | B9: 1 October 2026
A10: Model horizon | B10: Year 0 + Year 1 to Year 5 (₹, rupees)
A11: GITHUB link for REPORT | B11: https://github.com/harleenkaur20243/Financial-Modelling.git
A12: LINKED IN URL | B12: www.linkedin.com/in/harleen-kaur-b376a0379
A14: SHEET GUIDE
A15: 01-03 | B15: Project definition · Data & source register · AI research log
A16: 04 | B16: Assumption register (all inputs live here)
A17: 05-11 | B17: Operating drivers · investment & funding · revenue · costs · depreciation · debt · working capital
A18: 12-14 | B18: Income statement · cash flow · balance sheet (integrated; balance check = 0)
A19: 15-16 | B19: Project free cash flow · NPV, IRR, payback and decision
A20: 17-19 | B20: Break-even · scenarios · sensitivity
A21: 20-22 | B21: Dashboard · report & pitch outline · QA checks & viva preparation

Sheet 01_Project_Definition
A1: 01 · Project Definition
A4: Field | B4: Entry | C4: Quality test
A5: Project name | B5: Campus Brew Café | C5: Reader knows what is evaluated
A6: Business problem | B6: Students and staff around LPU want an affordable, comfortable place to eat, meet and study, but seating near the campus gate is limited at peak times. | C6: Measurable: crowding at peak hours
A7: Solution | B7: A 30-seat café serving beverages, snacks and meal combos at student-friendly prices. | C7: Directly linked to the need
A8: Target customer | B8: LPU students, faculty and staff, plus highway travellers on GT Road (LPU has 30,000+ students). | C8: Specific segment
A9: Geography | B9: Near LPU, Chaheru, Phagwara, Punjab (GT Road, NH-44 corridor). | C9: Matches data collected
A10: Business model (one sentence) | B10: The project invests about ₹ the amount in 06_Investment_Funding to provide food and beverages to students and staff in the LPU catchment in Phagwara, generating revenue through per-customer bills. | C10: Revenue mechanism explicit
A11: Unit of economics | B11: One paid customer visit (bill). Customers = seats × seat turns per day × days open. | C11: Measurable revenue unit
A12: Investment objective | B12: Capital for fit-out, equipment, licences, security deposit and opening cash buffer (Year-0 investment). | C12: Linked to 06_Investment_Funding
A13: Investment decision | B13: Invest / Invest with Conditions / Do Not Invest (see 16_Appraisal and 20_Dashboard). | C13: One of three outcomes

Sheet 02_Data_Sources
A1: 02 · Data & Source Register (audit trail)
A2: Official data sources providing reliable, justifiable and useful information
A4: Source ID | B4: Source name | C4: Type | D4: Date | E4: URL / reference | F4: Variable supported | G4: Value / range observed | H4: Unit | I4: Used in model | J4: Verification status / note | K4: Optional action to firm up
A5: SRC-01 | B5: Punjab minimum wages (WageIndicator, from state notification) | C5: Government notification via aggregator | D5: Eff. 1 May 2026 | E5: https://wageindicator.org/en-in/ai/work-in-india/minimum-wage/20772-punjab/ | F5: Staff pay floor | G5: Unskilled ₹518.69/day; semi-skilled ₹553.19; skilled ₹592.84 | H5: ₹/day | I5: 04 Assumptions C | J5: VERIFIED. Aggregator of the official Punjab notification. Salaries in the model are set at or above these floors. | K5: Cross-check with Punjab Labour Dept notification.
A6: SRC-02 | B6: The Tribune: PSERC tariff order FY2025-26 | C6: News report on official order | D6: FY2025-26 | E6: https://www.tribuneindia.com/news/punjab/no-change-in-power-tariff-for-domestic-commercial-users | F6: Electricity tariff | G6: Commercial ₹6.89-7.75 per kWh | H6: ₹/kWh | I6: 04 Assumptions D | J6: VERIFIED. Reputable newspaper reporting the official order. | K6: Check the PSERC FY2026-27 order on pserc.gov.in.
A7: SRC-03 | B7: PSERC Tariff Order FY2026-27 (news summaries: Babushahi, The Fact News) | C7: News report on official order | D7: 6 Mar 2026 | E7: https://www.babushahi.com/full-news.php?id=218071 | F7: Electricity tariff direction | G7: Non-residential energy charges reduced for FY2026-27 | H7: - | I7: 04 Assumptions D | J7: VERIFIED (direction). Confirms ₹7.2/kWh is conservative. | K7: Read the order on pserc.gov.in for the exact commercial rate.
A8: SRC-04 | B8: RBI repo rate (Aug 2026 MPC) | C8: Central bank | D8: Aug 2026 | E8: https://www.5paisa.com/blog/rbi-mpc-meeting-schedule; https://rbi.org.in/ | F8: Base lending rate | G8: Repo rate 5.25% | H8: % | I8: 04 Assumptions I | J8: VERIFIED. Repo rate unchanged at 5.25%. Loan rate = repo + estimated spread. | K8: Ask SBI/PNB for the MSME term-loan rate.
A9: SRC-05 | B9: Trading Economics: India 10-year G-Sec yield | C9: Market data | D9: 15 Sep 2026 | E9: https://tradingeconomics.com/india/government-bond-yield/news/583773 | F9: Risk-free rate | G9: About 7.1% | H9: % | I9: 04 Assumptions K | J9: VERIFIED. Market data provider; RBI/CCIL is the primary source. | K9: Confirm on rbi.org.in / CCIL.
A10: SRC-06 | B10: Trading Economics (CPI Aug 2026) and Akashvani/RBI policy statement | C10: Market data + official | D10: Aug-Sep 2026 | E10: https://newsonair.gov.in/rbi-to-announce-its-first-bi-monthly-monetary-policy-statement-for-financial-year-2026-27-today/ | F10: Inflation / price & cost growth | G10: CPI 4.82% (Aug 2026); RBI FY27 projection 4.6% | H10: % | I10: 04 Assumptions A, C, D | J10: VERIFIED (inflation figures). Pass-through to menu prices is an estimate. | K10: None needed.
A11: SRC-07 | B11: Careers360 (LPU profile) | C11: Education portal | D11: 2022-2024 | E11: https://www.careers360.com/question-location-of-lpu-phagwara-in-punjab | F11: Demand base | G11: 30,000+ students on a 600-acre campus on GT Road | H11: students | I11: 01 Project Definition; 04 turns ramp | J11: VERIFIED (secondary). Supports the size of the customer pool. | K11: Use LPU official website figures if available.
A12: SRC-08 | B12: Income Tax Act - concessional corporate rate (Sec. 115BAA) | C12: Statute | D12: Current | E12: https://incometax.gov.in | F12: Tax rate | G12: 22% + surcharge + cess = 25.17% | H12: % | I12: 04 Assumptions E | J12: STANDARD STATUTORY RATE. Well established; not re-opened during this session. | K12: Confirm on incometax.gov.in.
A13: SRC-09 | B13: FSSAI licence fee schedule / shop registration | C13: Regulator | D13: Current | E13: https://foscos.fssai.gov.in | F13: Licence costs | G13: ~₹30,000 setup; ~₹5,000 yearly renewals (estimate) | H13: ₹ | I13: 04 Assumptions D, G | J13: ESTIMATE. Fees to be confirmed on the FSSAI FoSCoS portal. | K13: Check FoSCoS fee page (5 minutes).
A14: SRC-10 | B14: Restaurant industry cost benchmarks (food cost 28-35% of sales; supplier credit 7-15 days) | C14: Industry rule of thumb | D14: General | E14: General industry practice | F14: Variable cost %, inventory and payable days | G14: 32% ingredients + 4% packaging | H14: % of sales | I14: 04 Assumptions B, F | J14: ESTIMATE (benchmark). Tested via sensitivity on variable cost. | K14: Cite a restaurant-industry report if available.
A15: SRC-11 | B15: Typical supplier price ranges (e.g. IndiaMART listings) for café equipment, furniture, fit-out | C15: Supplier listings | D15: General | E15: https://www.indiamart.com | F15: Capex items | G15: Equipment ₹8L, furniture ₹3.5L, interiors ₹6L, POS ₹0.8L | H15: ₹ | I15: 04 Assumptions G, H | J15: ESTIMATE. Not a formal quotation. | K15: One supplier quote or IndiaMART screenshot would upgrade this.
... A19: SRC-15 | B19: Bank MSME term-loan terms (SBI / PNB) | C19: Bank | D19: General | E19: https://sbi.co.in | F19: Debt share, tenor, spread | G19: 50% debt; 5 years; repo + ~4.75% | H19: - | I19: 04 Assumptions I | J19: ESTIMATE. Loan terms are indicative. | K19: Check SBI MSME loan page.

Sheet 03_AI_Research_Log
A1: 03 · AI Research Log
A2: Usage Of AI
A4: Date | B4: Tool | C4: Prompt / question | D4: AI output used | E4: Original source used to verify | F4: Verified fact | G4: Correction / rejection | H4: Final use in model
A5: 30/09/2026 | B5: Claude (Anthropic) | C5: Explain the FIN 545 assignment and suggest a project. | D5: Summary of the brief; project options (EV charging hub, café). | E5: Assignment PDF supplied by faculty. | F5: Rubric weights add up to 30 marks. | G5: EV charging hub rejected as too complex for the time available. | H5: Project choice: café near LPU.
A6: 30/09/2026 | B6: Claude (Anthropic) | C6: Find Punjab minimum wages effective 2026. | D6: Daily minimum wages by skill level. | E6: WageIndicator page reproducing the Punjab notification. | F6: Unskilled ₹518.69, semi-skilled ₹553.19, skilled ₹592.84 per day from 1 May 2026. | G6: None. | H6: Salary levels in 04_Assumptions.
A7: 30/09/2026 | B7: Claude (Anthropic) | C7: Find PSPCL / PSERC commercial electricity tariff. | D7: Tariff ranges for commercial consumers. | E7: The Tribune and Babushahi reports on PSERC tariff orders. | F7: Commercial ₹6.89-7.75/kWh in FY2025-26; non-residential charges reduced in FY2026-27. | G7: ₹7.2/kWh chosen as a conservative all-in rate. | H7: Electricity cost in 08_Cost_Model.
A8: 30/09/2026 | B8: Claude (Anthropic) | C8: Find RBI repo rate and 10-year G-Sec yield. | D8: Repo 5.25%; 10Y yield ~7.1%; CPI 4.82%. | E8: 5paisa/Akashvani (RBI policy); Trading Economics. | F8: Figures confirmed as of Aug-Sep 2026. | G8: Loan spread and equity premium are the modeller's estimates, not AI facts. | H8: Interest rate, risk-free rate, price growth.

Sheet 04_Assumptions
A1: 04 · Assumption Register (control centre)
A2: Assumptions set for the business model
A4: ID | B4: Assumption | C4: Value | D4: Unit | E4: Period | F4: Source ID | G4: Rationale / estimation method | H4: What happens if it is wrong | I4: Status
A5: A. OPERATING DRIVERS
A6: A02 | B6: Seating capacity | C6: 30 | D6: seats | E6: at launch | F6: SRC-12 | G6: Shop of ~750 sq ft at ~25 sq ft per seat (kitchen/counter take the rest). Capacity is the physical ceiling on customers. | H6: Fewer seats = lower revenue ceiling; more seats = higher rent/fit-out | I6: Estimate
A7: A03 | B7: Operating days per year | C7: 330 | D7: days/yr | E7: annual | F7: SRC-12 | G7: Open ~330 days; closed for festivals and some semester-break days near a university campus. | H7: Volume moves 1:1 with days | I7: Estimate
A8: A04 | B8: Average bill per customer (ex-GST) | C8: 160 | D8: ₹/customer | E8: Year 1 | F8: SRC-13 | G8: Typical campus-café ticket: a hot/cold beverage plus a snack or a meal combo. To confirm against menus of nearby cafés on Zomato/Swiggy. | H8: Revenue moves 1:1 (tested in sensitivity) | I8: Estimate
A9: A05 | B9: Annual price increase (Year 2-5) | C9: 0.05 | D9: % p.a. | E9: Year 2-5 | F9: SRC-06 | G9: Menu prices assumed to rise roughly with inflation. India CPI was 4.82% in Aug 2026 and RBI projects 4.6% for FY27. | H9: Lower price growth reduces later-year revenue | I9: Partly verified
A10: B. VARIABLE COSTS (change with number of customers)
A11: A07 | B11: Food & beverage ingredients | C11: 0.32 | D11: % of sales | E11: annual | F11: SRC-10 | G11: Cafés commonly run food cost near 28-35% of sales; 32% chosen. Rule-of-thumb benchmark, stress-tested in sensitivity. | H11: Each 1 pt of margin = 1% of sales in profit | I11: Estimate
A12: A08 | B12: Packaging & consumables | C12: 0.04 | D12: % of sales | E12: annual | F12: SRC-10 | G12: Cups, napkins, takeaway boxes, cleaning consumables. | H12: Small | I12: Estimate
A13: C. STAFF (fixed cost)
A14: A10 | B14: Cook / chef - headcount | C14: 1 | D14: persons | E14: annual | F14: SRC-01 | G14: One skilled cook for kitchen operations. | H14: Understaffing hurts service | I14: Estimate
A15: A11 | B15: Cook / chef - salary | C15: 22000 | D15: ₹/month | E15: monthly | F15: SRC-01 | G15: Above Punjab skilled minimum wage (₹592.84/day ≈ ₹15,400/month for 26 days). | H15: Payroll is the biggest fixed cost | I15: Floor verified; level estimated
A16: A12 | B16: Counter / service staff - headcount | C16: 2 | D16: persons | E16: annual | F16: SRC-01 | G16: Two staff for counter and table service. | I16: Estimate
A17: A13 | B17: Counter / service staff - salary | C17: 15000 | D17: ₹/month | E17: monthly | F17: SRC-01 | G17: Above semi-skilled minimum wage (₹553.19/day ≈ ₹14,400/month). | I17: Floor verified; level estimated
A18: A14 | B18: Helper - headcount | C18: 1 | D18: persons | E18: annual | F18: SRC-01 | G18: Cleaning and dishwashing. | I18: Estimate
A19: A15 | B19: Helper - salary | C19: 13500 | D19: ₹/month | E19: monthly | F19: SRC-01 | G19: At unskilled minimum wage (₹518.69/day ≈ ₹13,500/month). | I19: Floor verified
A20: A16 | B20: Manager - headcount | C20: 1 | D20: persons | E20: annual | F20: SRC-01 | G20: One manager to run the shop (owner-operator paid a salary). | I20: Estimate
A21: A17 | B21: Manager - salary | C21: 25000 | D21: ₹/month | E21: monthly | F21: SRC-01 | G21: Market-level manager pay for a small café. | I21: Estimate
A22: A18 | B22: Total base monthly payroll (calculated) | C22: =C14*C15+C16*C17+C18*C19+C20*C21 -> 90500 | D22: ₹/month | E22: monthly | F22: - | G22: Headcount × salary, summed. Formula, not an input. | I22: Calculated
A23: A19 | B23: Annual salary increase | C23: 0.06 | D23: % p.a. | E23: Year 2-5 | F23: SRC-06 | G23: Slightly above inflation to retain staff and follow minimum-wage revisions. | I23: Estimate
A24: A20 | B24: Statutory & other staff on-costs | C24: 0.08 | D24: % of salary | E24: annual | F24: SRC-01 | G24: PF/ESI, bonus and uniforms, added on top of salaries. | I24: Estimate
A25: D. RENT, UTILITIES & OTHER FIXED COSTS
A26: A22 | B26: Shop area rented | C26: 750 | D26: sq ft | E26: annual | F26: SRC-12 | G26: Matches 30-seat layout. | I26: Estimate
A27: A23 | B27: Rent per sq ft | C27: 90 | D27: ₹/sq ft/month | E27: monthly | F27: SRC-12 | G27: Commercial shop rent on GT Road / near campus. Replace with an actual listing or landlord quote if you can. | H27: Rent is ~25% of fixed costs | I27: Estimate
A28: A24 | B28: Annual rent escalation | C28: 0.05 | D28: % p.a. | E28: Year 2-5 | F28: SRC-12 | G28: Typical lease escalation of ~5% a year. | I28: Estimate
A29: A25 | B29: Electricity use at Year-1 volume | C29: 2000 | D29: kWh/month | E29: monthly | F29: SRC-02 | G29: AC, refrigeration, lighting, kitchen appliances. | I29: Estimate
A30: A26 | B30: Share of electricity that is fixed (rest moves with customers) | C30: 0.6 | D30: % | E30: annual | F30: SRC-02 | G30: Semi-variable cost: fridges and lighting are constant, cooking/AC load rises with customers. | I30: Estimate
A31: A27 | B31: Electricity tariff (commercial, all-in) | C31: 7.2 | D31: ₹/kWh | E31: Year 1 | F31: SRC-02 | G31: PSERC commercial tariff was ₹6.89-7.75/kWh in FY2025-26; FY2026-27 order reduced non-residential energy charges. ₹7.2 is a conservative all-in figure. | H31: Small effect | I31: Verified range
A32: A28 | B32: LPG, water & other kitchen utilities | C32: 6000 | D32: ₹/month | E32: monthly | F32: SRC-12 | G32: Cooking gas and water. | I32: Estimate
A33: A29 | B33: Marketing & promotions | C33: 8000 | D33: ₹/month | E33: monthly | F33: SRC-13 | G33: Social media, student offers, loyalty discounts. Fixed budget. | I33: Estimate
A34: A30 | B34: Insurance | C34: 25000 | D34: ₹/year | E34: annual | F34: SRC-12 | G34: Fire and contents cover. | I34: Estimate
A35: A31 | B35: Other fixed costs (accounting, POS subscription, cleaning) | C35: 6000 | D35: ₹/month | E35: monthly | F35: SRC-12 | G35: Bookkeeping, software, misc. | I35: Estimate
A36: A32 | B36: Licence renewals (FSSAI, shop registration) | C36: 5000 | D36: ₹/year | E36: annual | F36: SRC-09 | G36: Annual renewal of food-safety and shop licences. | I36: Estimate
A37: A33 | B37: Maintenance (% of equipment, furniture & tech cost) | C37: 0.03 | D37: % of cost | E37: annual | F37: SRC-11 | G37: Repairs and servicing; kept separate from capex. | I37: Estimate
A38: A34 | B38: General cost inflation (utilities, marketing, insurance, other) | C38: 0.05 | D38: % p.a. | E38: Year 2-5 | F38: SRC-06 | G38: In line with CPI trend. | I38: Partly verified
A39: E. TAX
A40: A36 | B40: Corporate income tax rate | C40: 0.2517 | D40: % | E40: annual | F40: SRC-08 | G40: Domestic company under the concessional regime (22% + surcharge + cess = 25.17%). Losses are not carried forward (conservative). | H40: Tax only bites once profits appear | I40: Statutory
A41: F. WORKING CAPITAL
...

Sheet 05_Operating_Drivers
A1: 05 · Operating Drivers
A2: Revenue is built from physical capacity: seats × how often each seat is used × average bill
A4: ₹ (unless stated) | B4: Type / unit | C4: Year 0 | D4: Year 1 | E4: Year 2 | F4: Year 3 | G4: Year 4 | H4: Year 5
A5: Year index (used in formulas) | C5: 0 | D5: 1 | E5: 2 | F5: 3 | G5: 4 | H5: 5
A6: Units: seating capacity | B6: seats | D6: ='04_Assumptions'!$C$6 -> 30 | E6: ='04_Assumptions'!$C$6 -> 30 | F6: ='04_Assumptions'!$C$6 -> 30 | G6: ='04_Assumptions'!$C$6 -> 30 | H6: ='04_Assumptions'!$C$6 -> 30
A7: Seat turns per day | B7: turns/day | D7: ='04_Assumptions'!$C$78 -> 2.5 | E7: ='04_Assumptions'!$D$78 -> 3 | F7: ='04_Assumptions'!$E$78 -> 3.5 | G7: ='04_Assumptions'!$F$78 -> 3.8 | H7: ='04_Assumptions'!$G$78 -> 4
A8: Operating days | B8: days | D8: ='04_Assumptions'!$C$7 -> 330 | E8: ='04_Assumptions'!$C$7 -> 330 | F8: ='04_Assumptions'!$C$7 -> 330 | G8: ='04_Assumptions'!$C$7 -> 330 | H8: ='04_Assumptions'!$C$7 -> 330
A9: Transactions per unit per year (fills per seat) | B9: per seat/yr | D9: =D7*D8 -> 825 | E9: =E7*E8 -> 990 | F9: =F7*F8 -> 1155 | G9: =G7*G8 -> 1254 | H9: =H7*H8 -> 1320
A10: Average price per transaction (bill) | B10: ₹/customer | D10: ='04_Assumptions'!$C$8*(1+'04_Assumptions'!$C$9)^(D$5-1) -> 160 | E10: ='04_Assumptions'!$C$8*(1+'04_Assumptions'!$C$9)^(E$5-1) -> 168 | F10: ='04_Assumptions'!$C$8*(1+'04_Assumptions'!$C$9)^(F$5-1) -> 176.4 | G10: ='04_Assumptions'!$C$8*(1+'04_Assumptions'!$C$9)^(G$5-1) -> 185.22 | H10: ='04_Assumptions'!$C$8*(1+'04_Assumptions'!$C$9)^(H$5-1) -> 194.481
A11: Total customers per year | B11: customers | D11: =D6*D9 -> 24750 | E11: =E6*E9 -> 29700 | F11: =F6*F9 -> 34650 | G11: =G6*G9 -> 37620 | H11: =H6*H9 -> 39600
A12: Customers per day | B12: customers/day | D12: =D11/D8 -> 75 | E12: =E11/E8 -> 90 | F12: =F11/F8 -> 105 | G12: =G11/G8 -> 114 | H12: =H11/H8 -> 120
A14: Unit of economics: ONE CUSTOMER VISIT (a paid bill). Customers = seats × turns/day × days open.

Sheet 06_Investment_Funding
A1: 06 · Year-0 Investment & Funding
A2: Cash committed before the café opens. Funding must equal investment.
A4: Investment item | B4: ₹ | C4: Basis
A5: Kitchen equipment | B5: ='04_Assumptions'!$C$47 -> 800000 | C5: Assumption G
A6: Furniture & fixtures | B6: ='04_Assumptions'!$C$48 -> 350000 | C6: Assumption G
A7: Interiors / fit-out | B7: ='04_Assumptions'!$C$49 -> 600000 | C7: Assumption G
A8: POS, software & CCTV | B8: ='04_Assumptions'!$C$50 -> 80000 | C8: Assumption G
A9: Licences & registration | B9: ='04_Assumptions'!$C$51 -> 30000 | C9: Assumption G
A10: Pre-opening & setup | B10: ='04_Assumptions'!$C$52 -> 120000 | C10: Assumption G
A11: Contingency | B11: ='04_Assumptions'!$C$53*SUM(B5:B10) -> 99000 | C11: 5% of items above
A12: Fixed assets & pre-operative expenses | B12: =SUM(B5:B11) -> 2079000
A13: Refundable security deposit | B13: ='04_Assumptions'!$C$54*'04_Assumptions'!$C$26*'04_Assumptions'!$C$27 -> 202500 | C13: Months of Year-1 rent (refunded at end of lease)
A14: Initial working capital (opening cash buffer) | B14: ='04_Assumptions'!$C$45/12*('08_Cost_Model'!D9+'08_Cost_Model'!D21) -> 648030 | C14: Months of Year-1 operating cost from 08_Cost_Model (not arbitrary)
A15: TOTAL INITIAL INVESTMENT (Year 0) | B15: =B12+B13+B14 -> 2929530
A18: FUNDING | B18: ₹ | C18: Basis
A19: Bank term loan (debt) | B19: ='04_Assumptions'!$C$62*B15 -> 1464765 | C19: Debt share × total investment
A20: Promoter equity | B20: =B15-B19 -> 1464765 | C20: Balancing: total investment − debt
A21: Total funding | B21: =B19+B20 -> 2929530
A22: Check: funding − investment (must be 0) | B22: =ROUND(B21-B15,2) -> 0
A24: Split used for depreciation: physical assets = rows 5-8; pre-operative = licences + pre-opening + contingency.

Sheet 07_Revenue_Model
A1: 07 · Driver-Based Revenue Model
A2: Revenue = Units × Transactions per unit × Average price (all linked from 05_Operating_Drivers).
A4: ₹ (unless stated) | B4: Type / unit | C4: Year 0 | D4: Year 1 | E4: Year 2 | F4: Year 3 | G4: Year 4 | H4: Year 5
A5: Year index (used in formulas) | C5: 0 | D5: 1 | E5: 2 | F5: 3 | G5: 4 | H5: 5
A6: Units (seats) | B6: seats | D6: ='05_Operating_Drivers'!D6 -> 30 | E6: ='05_Operating_Drivers'!E6 -> 30 | F6: ='05_Operating_Drivers'!F6 -> 30 | G6: ='05_Operating_Drivers'!G6 -> 30 | H6: ='05_Operating_Drivers'!H6 -> 30
A7: Transactions per unit per year | B7: per seat | D7: ='05_Operating_Drivers'!D9 -> 825 | E7: ='05_Operating_Drivers'!E9 -> 990 | F7: ='05_Operating_Drivers'!F9 -> 1155 | G7: ='05_Operating_Drivers'!G9 -> 1254 | H7: ='05_Operating_Drivers'!H9 -> 1320
A8: Average price per transaction | B8: ₹ | D8: ='05_Operating_Drivers'!D10 -> 160 | E8: ='05_Operating_Drivers'!E10 -> 168 | F8: ='05_Operating_Drivers'!F10 -> 176.4 | G8: ='05_Operating_Drivers'!G10 -> 185.22 | H8: ='05_Operating_Drivers'!H10 -> 194.481
A9: Core revenue (café sales) | B9: ₹ | D9: =D6*D7*D8 -> 3960000 | E9: =E6*E7*E8 -> 4989600 | F9: =F6*F7*F8 -> 6112260 | G9: =G6*G7*G8 -> 6967976.4 | H9: =H6*H7*H8 -> 7701447.6
A10: Other revenue (none assumed) | B10: ₹ | D10: 0 | E10: 0 | F10: 0 | G10: 0 | H10: 0 | I10: No second revenue stream assumed.
A11: Total revenue (ex-GST) | B11: ₹ | D11: =D9+D10 -> 3960000 | E11: =E9+E10 -> 4989600 | F11: =F9+F10 -> 6112260 | G11: =G9+G10 -> 6967976.4 | H11: =H9+H10 -> 7701447.6
A12: Revenue growth | B12: % | E12: =E11/D11-1 -> 0.26 | F12: =F11/E11-1 -> 0.225 | G12: =G11/F11-1 -> 0.14 | H12: =H11/G11-1 -> 0.10526316

Sheet 08_Cost_Model
A1: 08 · Driver-Based Cost Model
A2: Variable, fixed and semi-variable costs kept separate. Variable = % of sales; fixed = documented amounts; electricity is semi-variable.
A4: ₹ (unless stated) | B4: Type / unit | C4: Year 0 | D4: Year 1 | E4: Year 2 | F4: Year 3 | G4: Year 4 | H4: Year 5
A5: Year index (used in formulas) | C5: 0 | D5: 1 | E5: 2 | F5: 3 | G5: 4 | H5: 5
A6: Customers per year | B6: driver | D6: ='05_Operating_Drivers'!D11 -> 24750 | E6: ='05_Operating_Drivers'!E11 -> 29700 | F6: ='05_Operating_Drivers'!F11 -> 34650 | G6: ='05_Operating_Drivers'!G11 -> 37620 | H6: ='05_Operating_Drivers'!H11 -> 39600
A7: Ingredients (F&B cost) | B7: Variable | D7: ='07_Revenue_Model'!D11*'04_Assumptions'!$C$11 -> 1267200 | E7: ='07_Revenue_Model'!E11*'04_Assumptions'!$C$11 -> 1596672 | F7: ='07_Revenue_Model'!F11*'04_Assumptions'!$C$11 -> 1955923.2 | G7: ='07_Revenue_Model'!G11*'04_Assumptions'!$C$11 -> 2229752.4 | H7: ='07_Revenue_Model'!H11*'04_Assumptions'!$C$11 -> 2464463.2
A8: Packaging & consumables | B8: Variable | D8: ='07_Revenue_Model'!D11*'04_Assumptions'!$C$12 -> 158400 | E8: ='07_Revenue_Model'!E11*'04_Assumptions'!$C$12 -> 199584 | F8: ='07_Revenue_Model'!F11*'04_Assumptions'!$C$12 -> 244490.4 | G8: ='07_Revenue_Model'!G11*'04_Assumptions'!$C$12 -> 278719.06 | H8: ='07_Revenue_Model'!H11*'04_Assumptions'!$C$12 -> 308057.9
A9: Total variable cost | B9: Variable | D9: =D7+D8 -> 1425600 | E9: =E7+E8 -> 1796256 | F9: =F7+F8 -> 2200413.6 | G9: =G7+G8 -> 2508471.5 | H9: =H7+H8 -> 2772521.1
A10: Variable cost per customer | B10: ₹/customer | D10: =D9/D6 -> 57.6 | E10: =E9/E6 -> 60.48 | F10: =F9/F6 -> 63.504 | G10: =G9/G6 -> 66.6792 | H10: =H9/H6 -> 70.01316
A12: Salaries incl. on-costs | B12: Fixed | D12: ='04_Assumptions'!$C$22*12*(1+'04_Assumptions'!$C$23)^(D$5-1)*(1+'04_Assumptions'!$C$24) -> 1172880 | E12: ='04_Assumptions'!$C$22*12*(1+'04_Assumptions'!$C$23)^(E$5-1)*(1+'04_Assumptions'!$C$24) -> 1243252.8 | F12: ='04_Assumptions'!$C$22*12*(1+'04_Assumptions'!$C$23)^(F$5-1)*(1+'04_Assumptions'!$C$24) -> 1317848 | G12: ='04_Assumptions'!$C$22*12*(1+'04_Assumptions'!$C$23)^(G$5-1)*(1+'04_Assumptions'!$C$24) -> 1396918.8 | H12: ='04_Assumptions'!$C$22*12*(1+'04_Assumptions'!$C$23)^(H$5-1)*(1+'04_Assumptions'!$C$24) -> 1480734 | I12: Headcount × salary × 12, +6% p.a., +8% on-costs
A13: Rent | B13: Fixed | D13: ='04_Assumptions'!$C$26*'04_Assumptions'!$C$27*12*(1+'04_Assumptions'!$C$28)^(D$5-1) -> 810000 | E13: ='04_Assumptions'!$C$26*'04_Assumptions'!$C$27*12*(1+'04_Assumptions'!$C$28)^(E$5-1) -> 850500 | F13: ='04_Assumptions'!$C$26*'04_Assumptions'!$C$27*12*(1+'04_Assumptions'!$C$28)^(F$5-1) -> 893025 | G13: ='04_Assumptions'!$C$26*'04_Assumptions'!$C$27*12*(1+'04_Assumptions'!$C$28)^(G$5-1) -> 937676.25 | H13: ='04_Assumptions'!$C$26*'04_Assumptions'!$C$27*12*(1+'04_Assumptions'!$C$28)^(H$5-1) -> 984560.06 | I13: Area × rate × 12, +5% p.a.
A14: Electricity | B14: Semi-variable | D14: ='04_Assumptions'!$C$29*('04_Assumptions'!$C$30+(1-'04_Assumptions'!$C$30)*D6/$D6)*'04_Assumptions'!$C$31*12*(1+'04_Assumptions'!$C$38)^(D$5-1) -> 172800 | E14: ='04_Assumptions'!$C$29*('04_Assumptions'!$C$30+(1-'04_Assumptions'!$C$30)*E6/$D6)*'04_Assumptions'!$C$31*12*(1+'04_Assumptions'!$C$38)^(E$5-1) -> 195955.2 | F14: ='04_Assumptions'!$C$29*('04_Assumptions'!$C$30+(1-'04_Assumptions'!$C$30)*F6/$D6)*'04_Assumptions'!$C$31*12*(1+'04_Assumptions'!$C$38)^(F$5-1) -> 220993.92 | G14: ='04_Assumptions'!$C$29*('04_Assumptions'!$C$30+(1-'04_Assumptions'!$C$30)*G6/$D6)*'04_Assumptions'!$C$31*12*(1+'04_Assumptions'!$C$38)^(G$5-1) -> 241645.42 | H14: ='04_Assumptions'!$C$29*('04_Assumptions'!$C$30+(1-'04_Assumptions'!$C$30)*H6/$D6)*'04_Assumptions'!$C$31*12*(1+'04_Assumptions'!$C$38)^(H$5-1) -> 260448.96 | I14: 60% fixed + 40% moves with customers
A15: LPG, water & kitchen utilities | B15: Fixed | D15: ='04_Assumptions'!$C$32*12*(1+'04_Assumptions'!$C$38)^(D$5-1) -> 72000 | E15: ='04_Assumptions'!$C$32*12*(1+'04_Assumptions'!$C$38)^(E$5-1) -> 75600 | F15: ='04_Assumptions'!$C$32*12*(1+'04_Assumptions'!$C$38)^(F$5-1) -> 79380 | G15: ='04_Assumptions'!$C$32*12*(1+'04_Assumptions'!$C$38)^(G$5-1) -> 83349 | H15: ='04_Assumptions'!$C$32*12*(1+'04_Assumptions'!$C$38)^(H$5-1) -> 87516.45
A16: Marketing | B16: Fixed | D16: ='04_Assumptions'!$C$33*12*(1+'04_Assumptions'!$C$38)^(D$5-1) -> 96000 | E16: ='04_Assumptions'!$C$33*12*(1+'04_Assumptions'!$C$38)^(E$5-1) -> 100800 | F16: ='04_Assumptions'!$C$33*12*(1+'04_Assumptions'!$C$38)^(F$5-1) -> 105840 | G16: ='04_Assumptions'!$C$33*12*(1+'04_Assumptions'!$C$38)^(G$5-1) -> 111132 | H16: ='04_Assumptions'!$C$33*12*(1+'04_Assumptions'!$C$38)^(H$5-1) -> 116688.6
A17: Insurance | B17: Fixed | D17: ='04_Assumptions'!$C$34*(1+'04_Assumptions'!$C$38)^(D$5-1) -> 25000 | E17: ='04_Assumptions'!$C$34*(1+'04_Assumptions'!$C$38)^(E$5-1) -> 26250 | F17: ='04_Assumptions'!$C$34*(1+'04_Assumptions'!$C$38)^(F$5-1) -> 27562.5 | G17: ='04_Assumptions'!$C$34*(1+'04_Assumptions'!$C$38)^(G$5-1) -> 28940.625 | H17: ='04_Assumptions'!$C$34*(1+'04_Assumptions'!$C$38)^(H$5-1) -> 30387.656
A18: Maintenance | B18: Fixed | D18: ='04_Assumptions'!$C$37*('04_Assumptions'!$C$47+'04_Assumptions'!$C$48+'04_Assumptions'!$C$50)*(1+'04_Assumptions'!$C$38)^(D$5-1) -> 36900 | E18: ='04_Assumptions'!$C$37*('04_Assumptions'!$C$47+'04_Assumptions'!$C$48+'04_Assumptions'!$C$50)*(1+'04_Assumptions'!$C$38)^(E$5-1) -> 38745 | F18: ='04_Assumptions'!$C$37*('04_Assumptions'!$C$47+'04_Assumptions'!$C$48+'04_Assumptions'!$C$50)*(1+'04_Assumptions'!$C$38)^(F$5-1) -> 40682.25 | G18: ='04_Assumptions'!$C$37*('04_Assumptions'!$C$47+'04_Assumptions'!$C$48+'04_Assumptions'!$C$50)*(1+'04_Assumptions'!$C$38)^(G$5-1) -> 42716.363 | H18: ='04_Assumptions'!$C$37*('04_Assumptions'!$C$47+'04_Assumptions'!$C$48+'04_Assumptions'!$C$50)*(1+'04_Assumptions'!$C$38)^(H$5-1) -> 44852.181
A19: Licence renewals | B19: Fixed | D19: ='04_Assumptions'!$C$36*(1+'04_Assumptions'!$C$38)^(D$5-1) -> 5000 | E19: ='04_Assumptions'!$C$36*(1+'04_Assumptions'!$C$38)^(E$5-1) -> 5250 | F19: ='04_Assumptions'!$C$36*(1+'04_Assumptions'!$C$38)^(F$5-1) -> 5512.5 | G19: ='04_Assumptions'!$C$36*(1+'04_Assumptions'!$C$38)^(G$5-1) -> 5788.125 | H19: ='04_Assumptions'!$C$36*(1+'04_Assumptions'!$C$38)^(H$5-1) -> 6077.5312
A20: Other fixed costs | B20: Fixed | D20: ='04_Assumptions'!$C$35*12*(1+'04_Assumptions'!$C$38)^(D$5-1) -> 72000 | E20: ='04_Assumptions'!$C$35*12*(1+'04_Assumptions'!$C$38)^(E$5-1) -> 75600 | F20: ='04_Assumptions'!$C$35*12*(1+'04_Assumptions'!$C$38)^(F$5-1) -> 79380 | G20: ='04_Assumptions'!$C$35*12*(1+'04_Assumptions'!$C$38)^(G$5-1) -> 83349 | H20: ='04_Assumptions'!$C$35*12*(1+'04_Assumptions'!$C$38)^(H$5-1) -> 87516.45
A21: Total fixed & semi-variable operating cost | B21: Fixed | D21: =SUM(D12:D20) -> 2462580 | E21: =SUM(E12:E20) -> 2611953 | F21: =SUM(F12:F20) -> 2770224.1 | G21: =SUM(G12:G20) -> 2931515.6 | H21: =SUM(H12:H20) -> 3098781.9
A22: Total operating cost (before depreciation & interest) | D22: =D9+D21 -> 3888180 | E22: =E9+E21 -> 4408209 | F22: =F9+F21 -> 4970637.7 | G22: =G9+G21 -> 5439987.1 | H22: =H9+H21 -> 5871303
A24: Quality test: if revenue doubled, ingredients and packaging double, electricity rises partly (40% moves), and salaries/rent stay fixed.

Sheet 09_Assets_Depreciation
A1: 09 · Asset Register & Depreciation
A2: (Straight-line depreciation. Depreciation is non-cash: it reduces profit and tax but is added back in cash flow.)
A4: Asset | B4: Initial cost ₹ | C4: Useful life (yrs) | D4: Method | E4: Annual depreciation | F4: Year-1 NBV | G4: Year-5 NBV | H4: Source / basis
A5: Kitchen equipment | B5: ='06_Investment_Funding'!B5 -> 800000 | C5: ='04_Assumptions'!$C$56 -> 8 | D5: Straight-line | E5: =B5/C5 -> 100000 | F5: =B5-E5 -> 700000 | G5: =MAX(0,B5-E5*MIN(5,C5)) -> 300000 | H5: SRC-11
A6: Furniture & fixtures | B6: ='06_Investment_Funding'!B6 -> 350000 | C6: ='04_Assumptions'!$C$57 -> 8 | D6: Straight-line | E6: =B6/C6 -> 43750 | F6: =B6-E6 -> 306250 | G6: =MAX(0,B6-E6*MIN(5,C6)) -> 131250 | H6: SRC-11
A7: Interiors / fit-out | B7: ='06_Investment_Funding'!B7 -> 600000 | C7: ='04_Assumptions'!$C$58 -> 5 | D7: Straight-line | E7: =B7/C7 -> 120000 | F7: =B7-E7 -> 480000 | G7: =MAX(0,B7-E7*MIN(5,C7)) -> 0 | H7: SRC-12
A8: POS, software & CCTV | B8: ='06_Investment_Funding'!B8 -> 80000 | C8: ='04_Assumptions'!$C$59 -> 4 | D8: Straight-line | E8: =B8/C8 -> 20000 | F8: =B8-E8 -> 60000 | G8: =MAX(0,B8-E8*MIN(5,C8)) -> 0 | H8: SRC-11
A9: Pre-operative expenses (licences, pre-opening, contingency) | B9: ='06_Investment_Funding'!B9+'06_Investment_Funding'!B10+'06_Investment_Funding'!B11 -> 249000 | C9: ='04_Assumptions'!$C$60 -> 5 | D9: Straight-line | E9: =B9/C9 -> 49800 | F9: =B9-E9 -> 199200 | G9: =MAX(0,B9-E9*MIN(5,C9)) -> 0 | H9: SRC-11
A12: Year-wise schedule
A13: ₹ | B13: Type | C13: Year 0 | D13: Year 1 | E13: Year 2 | F13: Year 3 | G13: Year 4 | H13: Year 5
A14: Year index | C14: 0 | D14: 1 | E14: 2 | F14: 3 | G14: 4 | H14: 5
A15: Depreciation - Kitchen equipment | B15: Expense | D15: =IF(D$14<=$C$5,$B$5/$C$5,0) -> 100000 | E15: =IF(E$14<=$C$5,$B$5/$C$5,0) -> 100000 | F15: =IF(F$14<=$C$5,$B$5/$C$5,0) -> 100000 | G15: =IF(G$14<=$C$5,$B$5/$C$5,0) -> 100000 | H15: =IF(H$14<=$C$5,$B$5/$C$5,0) -> 100000
A16: Depreciation - Furniture & fixtures | B16: Expense | D16: =IF(D$14<=$C$6,$B$6/$C$6,0) -> 43750 | E16: =IF(E$14<=$C$6,$B$6/$C$6,0) -> 43750 | F16: =IF(F$14<=$C$6,$B$6/$C$6,0) -> 43750 | G16: =IF(G$14<=$C$6,$B$6/$C$6,0) -> 43750 | H16: =IF(H$14<=$C$6,$B$6/$C$6,0) -> 43750
A17: Depreciation - Interiors / fit-out | B17: Expense | D17: =IF(D$14<=$C$7,$B$7/$C$7,0) -> 120000 | E17: =IF(E$14<=$C$7,$B$7/$C$7,0) -> 120000 | F17: =IF(F$14<=$C$7,$B$7/$C$7,0) -> 120000 | G17: =IF(G$14<=$C$7,$B$7/$C$7,0) -> 120000 | H17: =IF(H$14<=$C$7,$B$7/$C$7,0) -> 120000
A18: Depreciation - POS, software & CCTV | B18: Expense | D18: =IF(D$14<=$C$8,$B$8/$C$8,0) -> 20000 | E18: =IF(E$14<=$C$8,$B$8/$C$8,0) -> 20000 | F18: =IF(F$14<=$C$8,$B$8/$C$8,0) -> 20000 | G18: =IF(G$14<=$C$8,$B$8/$C$8,0) -> 20000 | H18: =IF(H$14<=$C$8,$B$8/$C$8,0) -> 0
A19: Depreciation - Pre-operative expenses | B19: Expense | D19: =IF(D$14<=$C$9,$B$9/$C$9,0) -> 49800 | E19: =IF(E$14<=$C$9,$B$9/$C$9,0) -> 49800 | F19: =IF(F$14<=$C$9,$B$9/$C$9,0) -> 49800 | G19: =IF(G$14<=$C$9,$B$9/$C$9,0) -> 49800 | H19: =IF(H$14<=$C$9,$B$9/$C$9,0) -> 49800
A20: Total depreciation & amortisation | B20: Expense | D20: =SUM(D15:D19) -> 333550 | E20: =SUM(E15:E19) -> 333550 | F20: =SUM(F15:F19) -> 333550 | G20: =SUM(G15:G19) -> 333550 | H20: =SUM(H15:H19) -> 313550
A22: Net book value - Kitchen equipment | C22: =$B$5 -> 800000 | D22: =C22-D15 -> 700000 | E22: =D22-E15 -> 600000 | F22: =E22-F15 -> 500000 | G22: =F22-G15 -> 400000 | H22: =G22-H15 -> 300000
A23: Net book value - Furniture & fixtures | C23: =$B$6 -> 350000 | D23: =C23-D16 -> 306250 | E23: =D23-E16 -> 262500 | F23: =E23-F16 -> 218750 | G23: =F23-G16 -> 175000 | H23: =G23-H16 -> 131250
A24: Net book value - Interiors / fit-out | C24: =$B$7 -> 600000 | D24: =C24-D17 -> 480000 | E24: =D24-E17 -> 360000 | F24: =E24-F17 -> 240000 | G24: =F24-G17 -> 120000 | H24: =G24-H17 -> 0
A25: Net book value - POS, software & CCTV | C25: =$B$8 -> 80000 | D25: =C25-D18 -> 60000 | E25: =D25-E18 -> 40000 | F25: =E25-F18 -> 20000 | G25: =F25-G18 -> 0 | H25: =G25-H18 -> 0
A26: Net book value - Pre-operative expenses | C26: =$B$9 -> 249000 | D26: =C26-D19 -> 199200 | E26: =D26-E19 -> 149400 | F26: =E26-F19 -> 99600 | G26: =F26-G19 -> 49800 | H26: =G26-H19 -> 0
A27: Total net book value | C27: =SUM(C22:C26) -> 2079000 | D27: =SUM(D22:D26) -> 1745450 | E27: =SUM(E22:E26) -> 1411900 | F27: =SUM(F22:F26) -> 1078350 | G27: =SUM(G22:G26) -> 744800 | H27: =SUM(H22:H26) -> 431250
A28: NBV of physical assets (used for salvage) | C28: =SUM(C22:C25) -> 1830000 | D28: =SUM(D22:D25) -> 1546250 | E28: =SUM(E22:E25) -> 1262500 | F28: =SUM(F22:F25) -> 978750 | G28: =SUM(G22:G25) -> 695000 | H28: =SUM(H22:H25) -> 431250

Sheet 10_Debt_Schedule
A1: 10 · Debt Schedule
A2: Term loan with equal annual principal repayments. Interest is charged on the opening balance.
A4: ₹ (unless stated) | B4: Type / unit | C4: Year 0 | D4: Year 1 | E4: Year 2 | F4: Year 3 | G4: Year 4 | H4: Year 5
A5: Year index (used in formulas) | C5: 0 | D5: 1 | E5: 2 | F5: 3 | G5: 4 | H5: 5
A6: Opening debt | C6: 0 | D6: =C9 -> 1464765 | E6: =D9 -> 1171812 | F6: =E9 -> 878859 | G6: =F9 -> 585906 | H6: =G9 -> 292953
A7: New borrowing | C7: ='06_Investment_Funding'!B19 -> 1464765 | D7: 0 | E7: 0 | F7: 0 | G7: 0 | H7: 0
A8: Principal repayment | C8: 0 | D8: =MIN(D6,$C$7/'04_Assumptions'!$C$64) -> 292953 | E8: =MIN(E6,$C$7/'04_Assumptions'!$C$64) -> 292953 | F8: =MIN(F6,$C$7/'04_Assumptions'!$C$64) -> 292953 | G8: =MIN(G6,$C$7/'04_Assumptions'!$C$64) -> 292953 | H8: =MIN(H6,$C$7/'04_Assumptions'!$C$64) -> 292953
A9: Closing debt | C9: =C6+C7-C8 -> 1464765 | D9: =D6+D7-D8 -> 1171812 | E9: =E6+E7-E8 -> 878859 | F9: =F6+F7-F8 -> 585906 | G9: =G6+G7-G8 -> 292953 | H9: =H6+H7-H8 -> 0
A10: Interest rate | D10: ='04_Assumptions'!$C$63 -> 0.1 | E10: ='04_Assumptions'!$C$63 -> 0.1 | F10: ='04_Assumptions'!$C$63 -> 0.1 | G10: ='04_Assumptions'!$C$63 -> 0.1 | H10: ='04_Assumptions'!$C$63 -> 0.1
A11: Interest expense | D11: =D6*D10 -> 146476.5 | E11: =E6*E10 -> 117181.2 | F11: =F6*F10 -> 87885.9 | G11: =G6*G10 -> 58590.6 | H11: =H6*H10 -> 29295.3

Sheet 11_Working_Capital
A1: 11 · Working Capital
A2: Receivables, inventory and payables linked to the operating cycle. An increase in NWC uses cash.
A4: ₹ (unless stated) | B4: Type / unit | C4: Year 0 | D4: Year 1 | E4: Year 2 | F4: Year 3 | G4: Year 4 | H4: Year 5
A5: Year index (used in formulas) | C5: 0 | D5: 1 | E5: 2 | F5: 3 | G5: 4 | H5: 5
A6: Revenue | B6: link | D6: ='07_Revenue_Model'!D11 -> 3960000 | E6: ='07_Revenue_Model'!E11 -> 4989600 | F6: ='07_Revenue_Model'!F11 -> 6112260 | G6: ='07_Revenue_Model'!G11 -> 6967976.4 | H6: ='07_Revenue_Model'!H11 -> 7701447.6
A7: Variable cost | B7: link | D7: ='08_Cost_Model'!D9 -> 1425600 | E7: ='08_Cost_Model'!E9 -> 1796256 | F7: ='08_Cost_Model'!F9 -> 2200413.6 | G7: ='08_Cost_Model'!G9 -> 2508471.5 | H7: ='08_Cost_Model'!H9 -> 2772521.1
A8: Receivable days | B8: days | D8: ='04_Assumptions'!$C$42 -> 2 | E8: ='04_Assumptions'!$C$42 -> 2 | F8: ='04_Assumptions'!$C$42 -> 2 | G8: ='04_Assumptions'!$C$42 -> 2 | H8: ='04_Assumptions'!$C$42 -> 2
A9: Inventory days | B9: days | D9: ='04_Assumptions'!$C$43 -> 7 | E9: ='04_Assumptions'!$C$43 -> 7 | F9: ='04_Assumptions'!$C$43 -> 7 | G9: ='04_Assumptions'!$C$43 -> 7 | H9: ='04_Assumptions'!$C$43 -> 7
A10: Payable days | B10: days | D10: ='04_Assumptions'!$C$44 -> 10 | E10: ='04_Assumptions'!$C$44 -> 10 | F10: ='04_Assumptions'!$C$44 -> 10 | G10: ='04_Assumptions'!$C$44 -> 10 | H10: ='04_Assumptions'!$C$44 -> 10
A11: Accounts receivable | B11: Asset | C11: 0 | D11: =D6*D8/365 -> 21698.63 | E11: =E6*E8/365 -> 27340.274 | F11: =F6*F8/365 -> 33491.836 | G11: =G6*G8/365 -> 38180.693 | H11: =H6*H8/365 -> 42199.713
A12: Inventory | B12: Asset | C12: 0 | D12: =D7*D9/365 -> 27340.274 | E12: =E7*E9/365 -> 34448.745 | F12: =F7*F9/365 -> 42199.713 | G12: =G7*G9/365 -> 48107.673 | H12: =H7*H9/365 -> 53171.638
A13: Accounts payable | B13: Liability | C13: 0 | D13: =D7*D10/365 -> 39057.534 | E13: =E7*E10/365 -> 49212.493 | F13: =F7*F10/365 -> 60285.304 | G13: =G7*G10/365 -> 68725.247 | H13: =H7*H10/365 -> 75959.483
A14: Net working capital (AR + Inventory − AP) | C14: 0 | D14: =D11+D12-D13 -> 9981.3699 | E14: =E11+E12-E13 -> 12576.526 | F14: =F11+F12-F13 -> 15406.244 | G14: =G11+G12-G13 -> 17563.119 | H14: =H11+H12-H13 -> 19411.868
A15: Change in NWC (increase = cash used) | D15: =D14-C14 -> 9981.3699 | E15: =E14-D14 -> 2595.1562 | F15: =F14-E14 -> 2829.7184 | G15: =G14-F14 -> 2156.8742 | H15: =H14-G14 -> 1848.7493

Sheet 12_Income_Statement
A1: 12 · Projected Income Statement
A2: All figures linked from the schedules; nothing typed twice. Tax = 25.17% of positive profit only (no loss carry-forward).
A4: ₹ (unless stated) | B4: Type / unit | C4: Year 0 | D4: Year 1 | E4: Year 2 | F4: Year 3 | G4: Year 4 | H4: Year 5
A5: Year index (used in formulas) | C5: 0 | D5: 1 | E5: 2 | F5: 3 | G5: 4 | H5: 5
A6: Revenue | D6: ='07_Revenue_Model'!D11 -> 3960000 | E6: ='07_Revenue_Model'!E11 -> 4989600 | F6: ='07_Revenue_Model'!F11 -> 6112260 | G6: ='07_Revenue_Model'!G11 -> 6967976.4 | H6: ='07_Revenue_Model'!H11 -> 7701447.6
A7: Variable cost | D7: ='08_Cost_Model'!D9 -> 1425600 | E7: ='08_Cost_Model'!E9 -> 1796256 | F7: ='08_Cost_Model'!F9 -> 2200413.6 | G7: ='08_Cost_Model'!G9 -> 2508471.5 | H7: ='08_Cost_Model'!H9 -> 2772521.1
A8: Gross contribution | D8: =D6-D7 -> 2534400 | E8: =E6-E7 -> 3193344 | F8: =F6-F7 -> 3911846.4 | G8: =G6-G7 -> 4459504.9 | H8: =H6-H7 -> 4928926.5
A9: Fixed operating cost | D9: ='08_Cost_Model'!D21 -> 2462580 | E9: ='08_Cost_Model'!E21 -> 2611953 | F9: ='08_Cost_Model'!F21 -> 2770224.1 | G9: ='08_Cost_Model'!G21 -> 2931515.6 | H9: ='08_Cost_Model'!H21 -> 3098781.9
A10: EBITDA | D10: =D8-D9 -> 71820 | E10: =E8-E9 -> 581391 | F10: =F8-F9 -> 1141622.3 | G10: =G8-G9 -> 1527989.3 | H10: =H8-H9 -> 1830144.6
A11: Depreciation & amortisation | D11: ='09_Assets_Depreciation'!D20 -> 333550 | E11: ='09_Assets_Depreciation'!E20 -> 333550 | F11: ='09_Assets_Depreciation'!F20 -> 333550 | G11: ='09_Assets_Depreciation'!G20 -> 333550 | H11: ='09_Assets_Depreciation'!H20 -> 313550
A12: EBIT | D12: =D10-D11 -> -261730 | E12: =E10-E11 -> 247841 | F12: =F10-F11 -> 808072.26 | G12: =G10-G11 -> 1194439.3 | H12: =H10-H11 -> 1516594.6
A13: Interest expense | D13: ='10_Debt_Schedule'!D11 -> 146476.5 | E13: ='10_Debt_Schedule'!E11 -> 117181.2 | F13: ='10_Debt_Schedule'!F11 -> 87885.9 | G13: ='10_Debt_Schedule'!G11 -> 58590.6 | H13: ='10_Debt_Schedule'!H11 -> 29295.3
A14: Profit before tax | D14: =D12-D13 -> -408206.5 | E14: =E12-E13 -> 130659.8 | F14: =F12-F13 -> 720186.36 | G14: =G12-G13 -> 1135848.7 | H14: =H12-H13 -> 1487299.3
A15: Tax | D15: =MAX(0,D14)*'04_Assumptions'!$C$40 -> 0 | E15: =MAX(0,E14)*'04_Assumptions'!$C$40 -> 32887.072 | F15: =MAX(0,F14)*'04_Assumptions'!$C$40 -> 181270.91 | G15: =MAX(0,G14)*'04_Assumptions'!$C$40 -> 285893.11 | H15: =MAX(0,H14)*'04_Assumptions'!$C$40 -> 374353.23
A16: Net profit | D16: =D14-D15 -> -408206.5 | E16: =E14-E15 -> 97772.728 | F16: =F14-F15 -> 538915.45 | G16: =G14-G15 -> 849955.56 | H16: =H14-H15 -> 1112946.1
A17: EBITDA margin | D17: =D10/D6 -> 0.018136364 | E17: =E10/E6 -> 0.11652056 | F17: =F10/F6 -> 0.1867758 | G17: =G10/G6 -> 0.21928738 | H17: =H10/H6 -> 0.23763644
A18: Net profit margin | D18: =D16/D6 -> -0.10308245 | E18: =E16/E6 -> 0.019595304 | F18: =F16/F6 -> 0.088169589 | G18: =G16/G6 -> 0.12198026 | H18: =H16/H6 -> 0.14451128

Sheet 13_Cash_Flow
A1: 13 · Projected Cash Flow Statement
A2: Operating + investing + financing = net change in cash
A4: ₹ (unless stated) | B4: Type / unit | C4: Year 0 | D4: Year 1 | E4: Year 2 | F4: Year 3 | G4: Year 4 | H4: Year 5
A5: Year index (used in formulas) | C5: 0 | D5: 1 | E5: 2 | F5: 3 | G5: 4 | H5: 5
A6: Net profit | C6: 0 | D6: ='12_Income_Statement'!D16 -> -408206.5 | E6: ='12_Income_Statement'!E16 -> 97772.728 | F6: ='12_Income_Statement'!F16 -> 538915.45 | G6: ='12_Income_Statement'!G16 -> 849955.56 | H6: ='12_Income_Statement'!H16 -> 1112946.1
A7: Add: depreciation & amortisation (non-cash) | C7: 0 | D7: ='12_Income_Statement'!D11 -> 333550 | E7: ='12_Income_Statement'!E11 -> 333550 | F7: ='12_Income_Statement'!F11 -> 333550 | G7: ='12_Income_Statement'!G11 -> 333550 | H7: ='12_Income_Statement'!H11 -> 313550
A8: Less: increase in net working capital | C8: 0 | D8: -9981.3699 | E8: -2595.1562 | F8: -2829.7184 | G8: -2156.8742 | H8: -1848.7493
A9: Cash flow from operations | C9: =SUM(C6:C8) -> 0 | D9: =SUM(D6:D8) -> -84637.87 | E9: =SUM(E6:E8) -> 428727.57 | F9: =SUM(F6:F8) -> 869635.74 | G9: =SUM(G6:G8) -> 1181348.7 | H9: =SUM(H6:H8) -> 1424647.3
A11: Capex, pre-operative costs & security deposit | C11: =-('06_Investment_Funding'!B12+'06_Investment_Funding'!B13) -> -2281500 | D11: 0 | E11: 0 | F11: 0 | G11: 0 | H11: 0
A12: Cash flow from investing | C12: =C11 -> -2281500 | D12: =D11 -> 0 | E12: =E11 -> 0 | F12: =F11 -> 0 | G12: =G11 -> 0 | H12: =H11 -> 0
A14: New borrowing | C14: ='10_Debt_Schedule'!C7 -> 1464765 | D14: 0 | E14: 0 | F14: 0 | G14: 0 | H14: 0
A15: Promoter equity introduced | C15: ='06_Investment_Funding'!B20 -> 1464765 | D15: 0 | E15: 0 | F15: 0 | G15: 0 | H15: 0
A16: Principal repayment | C16: 0 | D16: -292953 | E16: -292953 | F16: -292953 | G16: -292953 | H16: -292953
A17: Cash flow from financing | C17: =SUM(C14:C16) -> 2929530 | D17: =SUM(D14:D16) -> -292953 | E17: =SUM(E14:E16) -> -292953 | F17: =SUM(F14:F16) -> -292953 | G17: =SUM(G14:G16) -> -292953 | H17: =SUM(H14:H16) -> -292953
A19: Net change in cash | C19: =C9+C12+C17 -> 648030 | D19: =D9+D12+D17 -> -377590.87 | E19: =E9+E12+E17 -> 135774.57 | F19: =F9+F12+F17 -> 576682.74 | G19: =G9+G12+G17 -> 888395.68 | H19: =H9+H12+H17 -> 1131694.3
A20: Opening cash | C20: 0 | D20: =C21 -> 648030 | E20: =D21 -> 270439.13 | F20: =E21 -> 406213.7 | G20: =F21 -> 982896.44 | H20: =G21 -> 1871292.1
A21: Closing cash | C21: =C20+C19 -> 648030 | D21: =D20+D19 -> 270439.13 | E21: =E20+E19 -> 406213.7 | F21: =F20+F19 -> 982896.44 | G21: =G20+G19 -> 1871292.1 | H21: =H20+H19 -> 3002986.4

Sheet 14_Balance_Sheet
A1: 14 · Projected Balance Sheet
A2: Control check: Total assets − (liabilities + equity) must be zero in every year.
A4: ₹ (unless stated) | B4: Type / unit | C4: Year 0 | D4: Year 1 | E4: Year 2 | F4: Year 3 | G4: Year 4 | H4: Year 5
A5: Year index (used in formulas) | C5: 0 | D5: 1 | E5: 2 | F5: 3 | G5: 4 | H5: 5
A6: Net fixed assets & unamortised pre-operative costs | C6: ='09_Assets_Depreciation'!C27 -> 2079000 | D6: ='09_Assets_Depreciation'!D27 -> 1745450 | E6: ='09_Assets_Depreciation'!E27 -> 1411900 | F6: ='09_Assets_Depreciation'!F27 -> 1078350 | G6: ='09_Assets_Depreciation'!G27 -> 744800 | H6: ='09_Assets_Depreciation'!H27 -> 431250
A7: Refundable security deposit | C7: ='06_Investment_Funding'!B13 -> 202500 | D7: ='06_Investment_Funding'!B13 -> 202500 | E7: ='06_Investment_Funding'!B13 -> 202500 | F7: ='06_Investment_Funding'!B13 -> 202500 | G7: ='06_Investment_Funding'!B13 -> 202500 | H7: ='06_Investment_Funding'!B13 -> 202500
A8: Accounts receivable | C8: ='11_Working_Capital'!C11 -> 0 | D8: ='11_Working_Capital'!D11 -> 21698.63 | E8: ='11_Working_Capital'!E11 -> 27340.274 | F8: ='11_Working_Capital'!F11 -> 33491.836 | G8: ='11_Working_Capital'!G11 -> 38180.693 | H8: ='11_Working_Capital'!H11 -> 42199.713
A9: Inventory | C9: ='11_Working_Capital'!C12 -> 0 | D9: ='11_Working_Capital'!D12 -> 27340.274 | E9: ='11_Working_Capital'!E12 -> 34448.745 | F9: ='11_Working_Capital'!F12 -> 42199.713 | G9: ='11_Working_Capital'!G12 -> 48107.673 | H9: ='11_Working_Capital'!H12 -> 53171.638
A10: Cash | C10: ='13_Cash_Flow'!C21 -> 648030 | D10: ='13_Cash_Flow'!D21 -> 270439.13 | E10: ='13_Cash_Flow'!E21 -> 406213.7 | F10: ='13_Cash_Flow'!F21 -> 982896.44 | G10: ='13_Cash_Flow'!G21 -> 1871292.1 | H10: ='13_Cash_Flow'!H21 -> 3002986.4
A11: TOTAL ASSETS | C11: =SUM(C6:C10) -> 2929530 | D11: =SUM(D6:D10) -> 2267428 | E11: =SUM(E6:E10) -> 2082402.7 | F11: =SUM(F6:F10) -> 2339438 | G11: =SUM(G6:G10) -> 2904880.5 | H11: =SUM(H6:H10) -> 3732107.8
A13: Accounts payable | C13: ='11_Working_Capital'!C13 -> 0 | D13: ='11_Working_Capital'!D13 -> 39057.534 | E13: ='11_Working_Capital'!E13 -> 49212.493 | F13: ='11_Working_Capital'!F13 -> 60285.304 | G13: ='11_Working_Capital'!G13 -> 68725.247 | H13: ='11_Working_Capital'!H13 -> 75959.483
A14: Bank term loan | C14: ='10_Debt_Schedule'!C9 -> 1464765 | D14: ='10_Debt_Schedule'!D9 -> 1171812 | E14: ='10_Debt_Schedule'!E9 -> 878859 | F14: ='10_Debt_Schedule'!F9 -> 585906 | G14: ='10_Debt_Schedule'!G9 -> 292953 | H14: ='10_Debt_Schedule'!H9 -> 0
A15: TOTAL LIABILITIES | C15: =C13+C14 -> 1464765 | D15: =D13+D14 -> 1210869.5 | E15: =E13+E14 -> 928071.49 | F15: =F13+F14 -> 646191.3 | G15: =G13+G14 -> 361678.25 | H15: =H13+H14 -> 75959.483
A17: Promoter equity (share capital) | C17: ='06_Investment_Funding'!B20 -> 1464765 | D17: ='06_Investment_Funding'!B20 -> 1464765 | E17: ='06_Investment_Funding'!B20 -> 1464765 | F17: ='06_Investment_Funding'!B20 -> 1464765 | G17: ='06_Investment_Funding'!B20 -> 1464765 | H17: ='06_Investment_Funding'!B20 -> 1464765
A18: Retained earnings | C18: 0 | D18: =C18+'12_Income_Statement'!D16 -> -408206.5 | E18: =D18+'12_Income_Statement'!E16 -> -310433.77 | F18: =E18+'12_Income_Statement'!F16 -> 228481.68 | G18: =F18+'12_Income_Statement'!G16 -> 1078437.2 | H18: =G18+'12_Income_Statement'!H16 -> 2191383.3
A19: TOTAL EQUITY | C19: =C17+C18 -> 1464765 | D19: =D17+D18 -> 1056558.5 | E19: =E17+E18 -> 1154331.2 | F19: =F17+F18 -> 1693246.7 | G19: =G17+G18 -> 2543202.2 | H19: =H17+H18 -> 3656148.3
A20: TOTAL LIABILITIES & EQUITY | C20: =C15+C19 -> 2929530 | D20: =D15+D19 -> 2267428 | E20: =E15+E19 -> 2082402.7 | F20: =F15+F19 -> 2339438 | G20: =G15+G19 -> 2904880.5 | H20: =H15+H19 -> 3732107.8
A22: BALANCE CHECK (must be 0) | C22: =ROUND(C11-C20,2) -> 0 | D22: =ROUND(D11-D20,2) -> 0 | E22: =ROUND(E11-E20,2) -> 0 | F22: =ROUND(F11-F20,2) -> 0 | G22: =ROUND(G11-G20,2) -> 0 | H22: =ROUND(H11-H20,2) -> 0

Sheet 15_Project_FCF
A1: 15 · Project Free Cash Flow
A2: Measures the café as a project, independent of how it is financed: NO interest, NO loan drawdown, NO principal repayment.
A4: ₹ (unless stated) | B4: Type / unit | C4: Year 0 | D4: Year 1 | E4: Year 2 | F4: Year 3 | G4: Year 4 | H4: Year 5
A5: Year index (used in formulas) | C5: 0 | D5: 1 | E5: 2 | F5: 3 | G5: 4 | H5: 5
A6: EBIT (operating profit) | D6: ='12_Income_Statement'!D12 -> -261730 | E6: ='12_Income_Statement'!E12 -> 247841 | F6: ='12_Income_Statement'!F12 -> 808072.26 | G6: ='12_Income_Statement'!G12 -> 1194439.3 | H6: ='12_Income_Statement'!H12 -> 1516594.6
A7: Tax on EBIT | D7: =MAX(0,D6)*'04_Assumptions'!$C$40 -> 0 | E7: =MAX(0,E6)*'04_Assumptions'!$C$40 -> 62381.58 | F7: =MAX(0,F6)*'04_Assumptions'!$C$40 -> 203391.79 | G7: =MAX(0,G6)*'04_Assumptions'!$C$40 -> 300640.36 | H7: =MAX(0,H6)*'04_Assumptions'!$C$40 -> 381726.86
A8: NOPAT (EBIT − tax on EBIT) | D8: =D6-D7 -> -261730 | E8: =E6-E7 -> 185459.42 | F8: =F6-F7 -> 604680.47 | G8: =G6-G7 -> 893798.9 | H8: =H6-H7 -> 1134867.7
A9: Add: depreciation & amortisation | D9: ='12_Income_Statement'!D11 -> 333550 | E9: ='12_Income_Statement'!E11 -> 333550 | F9: ='12_Income_Statement'!F11 -> 333550 | G9: ='12_Income_Statement'!G11 -> 333550 | H9: ='12_Income_Statement'!H11 -> 313550
A10: Less: capex & pre-operative costs | C10: -2079000 | D10: 0 | E10: 0 | F10: 0 | G10: 0 | H10: 0
A11: Less: security deposit paid | C11: -202500 | D11: 0 | E11: 0 | F11: 0 | G11: 0 | H11: 0
A12: Less: initial working capital (cash buffer) | C12: -648030 | D12: 0 | E12: 0 | F12: 0 | G12: 0 | H12: 0
A13: Less: increase in NWC | D13: -9981.3699 | E13: -2595.1562 | F13: -2829.7184 | G13: -2156.8742 | H13: -1848.7493
A14: After-tax salvage value of assets (Year 5) | C14: 0 | D14: 0 | E14: 0 | F14: 0 | G14: 0 | H14: ='04_Assumptions'!$C$66*'09_Assets_Depreciation'!H28-'04_Assumptions'!$C$40*MAX(0,'04_Assumptions'!$C$66*'09_Assets_Depreciation'!H28-'09_Assets_Depreciation'!H28) -> 107812.5
A15: Release of initial working capital (Year 5) | C15: 0 | D15: 0 | E15: 0 | F15: 0 | G15: 0 | H15: ='06_Investment_Funding'!B14 -> 648030
A16: Refund of security deposit (Year 5) | C16: 0 | D16: 0 | E16: 0 | F16: 0 | G16: 0 | H16: ='06_Investment_Funding'!B13 -> 202500
A17: PROJECT FREE CASH FLOW | C17: =C8+C9+SUM(C10:C16) -> -2929530 | D17: =D8+D9+SUM(D10:D16) -> 61838.63 | E17: =E8+E9+SUM(E10:E16) -> 516414.26 | F17: =F8+F9+SUM(F10:F16) -> 935400.76 | G17: =G8+G9+SUM(G10:G16) -> 1225192 | H17: =H8+H9+SUM(H10:H16) -> 2404911.5
A18: Cumulative Project FCF | C18: =C17 -> -2929530 | D18: =C18+D17 -> -2867691.4 | E18: =D18+E17 -> -2351277.1 | F18: =E18+F17 -> -1415876.4 | G18: =F18+G17 -> -190684.32 | H18: =G18+H17 -> 2214227.2
A20: Salvage: resale = 25% of physical-asset book value at Year 5; tax on any gain is zero because resale is below book value.

Sheet 16_Appraisal
A1: 16 · Investment Appraisal (NPV, IRR, Payback)
A2: All metrics use the SAME Project FCF series from 15_Project_FCF.
A4: ₹ (unless stated) | B4: Type / unit | C4: Year 0 | D4: Year 1 | E4: Year 2 | F4: Year 3 | G4: Year 4 | H4: Year 5
A5: Year index (used in formulas) | C5: 0 | D5: 1 | E5: 2 | F5: 3 | G5: 4 | H5: 5
A6: Required return (WACC) | C6: ='04_Assumptions'!$C$74 -> 0.132915
A8: Project FCF | C8: ='15_Project_FCF'!C17 -> -2929530 | D8: ='15_Project_FCF'!D17 -> 61838.63 | E8: ='15_Project_FCF'!E17 -> 516414.26 | F8: ='15_Project_FCF'!F17 -> 935400.76 | G8: ='15_Project_FCF'!G17 -> 1225192 | H8: ='15_Project_FCF'!H17 -> 2404911.5
A9: Cumulative Project FCF | C9: =C8 -> -2929530 | D9: =C9+D8 -> -2867691.4 | E9: =D9+E8 -> -2351277.1 | F9: =E9+F8 -> -1415876.4 | G9: =F9+G8 -> -190684.32 | H9: =G9+H8 -> 2214227.2
A10: Discount factor | C10: =1/(1+$C$6)^C$5 -> 1 | D10: =1/(1+$C$6)^D$5 -> 0.88267875 | E10: =1/(1+$C$6)^E$5 -> 0.77912178 | F10: =1/(1+$C$6)^F$5 -> 0.68771424 | G10: =1/(1+$C$6)^G$5 -> 0.60703075 | H10: =1/(1+$C$6)^H$5 -> 0.53581315
A11: Present value of FCF | C11: =C8*C10 -> -2929530 | D11: =D8*D10 -> 54583.645 | E11: =E8*E10 -> 402349.6 | F11: =F8*F10 -> 643288.42 | G11: =G8*G10 -> 743729.24 | H11: =H8*H10 -> 1288583.2
A12: Payback helper (fraction-of-year recovery) | D12: =IF(AND(C9<0,D9>=0),(D$5-1)+(-C9)/D8,0) -> 0 | E12: =IF(AND(D9<0,E9>=0),(E$5-1)+(-D9)/E8,0) -> 0 | F12: =IF(AND(E9<0,F9>=0),(F$5-1)+(-E9)/F8,0) -> 0 | G12: =IF(AND(F9<0,G9>=0),(G$5-1)+(-F9)/G8,0) -> 0 | H12: =IF(AND(G9<0,H9>=0),(H$5-1)+(-G9)/H8,0) -> 4.0792895
A15: NPV (₹) | C15: =C8+NPV(C6,D8:H8) -> 203004.1 | D15: Year-0 FCF + PV of Years 1-5 at the required return
A16: NPV cross-check (sum of PVs) | C16: =SUM(C11:H11) -> 203004.1
A17: Project IRR | C17: =IFERROR(IRR(C8:H8),"n/a") -> 0.15261855
A18: IRR minus required return | C18: =IFERROR(C17-C6,"n/a") -> 0.019703546
A19: Payback period (years) | C19: =IF(SUM(D12:H12)=0,"> 5 yrs",SUM(D12:H12)) -> 4.0792895
A20: Profitability index (PV of inflows ÷ investment) | C20: =1+C15/-C8 -> 1.0692958
A22: BASE-CASE DECISION | C22: =IF(AND(C15>0,ISNUMBER(C17),C17>C6),IF('18_Scenarios'!E12>0,"Invest","Invest with Conditions"),"Do Not Invest") -> Invest with Conditions
A23: Decision rule: "Invest" if NPV>0, IRR>required return AND the pessimistic NPV is also >0; "Invest with Conditions" if only the base case clears the hurdle; else "Do Not Invest".

Sheet 17_Break_Even
A1: 17 · Break-Even & Margin of Safety
A2: How many customers must the café serve to cover its fixed costs?
A4: Year-1 break-even (EBITDA level) | B4: Value
A5: Selling price per customer (Year 1) | B5: ='05_Operating_Drivers'!D10 -> 160
A6: Variable cost per customer (Year 1) | B6: ='08_Cost_Model'!D10 -> 57.6
A7: Contribution per customer | B7: =B5-B6 -> 102.4
A8: Contribution margin % | B8: =B7/B5 -> 0.64
A9: Annual fixed operating costs (Year 1) | B9: ='08_Cost_Model'!D21 -> 2462580
A10: Break-even customers per year | B10: =B9/B7 -> 24048.633
A11: Break-even customers per day | B11: =B10/'05_Operating_Drivers'!D8 -> 72.874645
A12: Break-even revenue per year (₹) | B12: =B10*B5 -> 3847781.2
A13: Projected Year-1 customers | B13: ='05_Operating_Drivers'!D11 -> 24750
A14: Margin of safety (customers) | B14: =B13-B10 -> 701.36719
A15: Margin of safety % | B15: =B14/B13 -> 0.028338068
A16: Break-even seat turns per day | B16: =B10/('05_Operating_Drivers'!D6*'05_Operating_Drivers'!D8) -> 2.4291548
A17: Reading | B17: =IF(B15>=0.25,"Comfortably above break-even",IF(B15>=0,"Only marginally above break-even in Year 1","Below break-even in Year 1 (expected while the café ramps up)")) -> Only marginally above break-even in Year 1
A19: Break-even by year | D19: Year 1 | E19: Year 2 | F19: Year 3 | G19: Year 4 | H19: Year 5
A20: Price per customer | D20: ='05_Operating_Drivers'!D10 -> 160 | E20: ='05_Operating_Drivers'!E10 -> 168 | F20: ='05_Operating_Drivers'!F10 -> 176.4 | G20: ='05_Operating_Drivers'!G10 -> 185.22 | H20: ='05_Operating_Drivers'!H10 -> 194.481
A21: Variable cost per customer | D21: ='08_Cost_Model'!D10 -> 57.6 | E21: ='08_Cost_Model'!E10 -> 60.48 | F21: ='08_Cost_Model'!F10 -> 63.504 | G21: ='08_Cost_Model'!G10 -> 66.6792 | H21: ='08_Cost_Model'!H10 -> 70.01316
A22: Fixed operating cost | D22: ='08_Cost_Model'!D21 -> 2462580 | E22: ='08_Cost_Model'!E21 -> 2611953 | F22: ='08_Cost_Model'!F21 -> 2770224.1 | G22: ='08_Cost_Model'!G21 -> 2931515.6 | H22: ='08_Cost_Model'!H21 -> 3098781.9
A23: Break-even customers per day | D23: =D22/(D20-D21)/'05_Operating_Drivers'!D8 -> 72.874645 | E23: =E22/(E20-E21)/'05_Operating_Drivers'!E8 -> 73.614296 | F23: =F22/(F20-F21)/'05_Operating_Drivers'!F8 -> 74.357095 | G23: =G22/(G20-G21)/'05_Operating_Drivers'!G8 -> 74.939436 | H23: =H22/(H20-H21)/'05_Operating_Drivers'!H8 -> 75.443167
A24: Projected customers per day | D24: ='05_Operating_Drivers'!D12 -> 75 | E24: ='05_Operating_Drivers'!E12 -> 90 | F24: ='05_Operating_Drivers'!F12 -> 105 | G24: ='05_Operating_Drivers'!G12 -> 114 | H24: ='05_Operating_Drivers'!H12 -> 120
A25: Margin of safety % | D25: =(D24-D23)/D24 -> 0.028338068 | E25: =(E24-E23)/E24 -> 0.18206338 | F25: =(F24-F23)/F24 -> 0.29183719 | G25: =(G24-G23)/G24 -> 0.34263653 | H25: =(H24-H23)/H24 -> 0.37130694
A27: Including depreciation and interest (full accounting break-even, Year 1)
A28: Break-even customers per day incl. depreciation & interest | B28: =(B9+'12_Income_Statement'!D11+'12_Income_Statement'!D13)/B7/'05_Operating_Drivers'!D8 -> 87.079975

Sheet 18_Scenarios
A1: 18 · Scenario Analysis
A2: Each scenario re-runs the whole economics (revenue → costs → tax → working capital → FCF → NPV/IRR). Year-0 investment is held at the base case.
A5: Scenario | B5: Volume change | C5: Price change | D5: Variable cost change | E5: Fixed cost change | F5: Justification
A6: Pessimistic | B6: -0.2 | C6: -0.1 | D6: 0.1 | E6: 0.1 | F6: Template downside: weaker footfall (semester break/competitor opening), discounting to win students, ingredient and rent pressure.
A7: Base | B7: 0 | C7: 0 | D7: 0 | E7: 0 | F7: Matches the base model exactly.
A8: Optimistic | B8: 0.2 | C8: 0.1 | D8: -0.05 | E8: -0.05 | F8: Template upside: strong student adoption, premium items, better supplier terms.
A11: Scenario | B11: Year-1 revenue | C11: Year-5 revenue | D11: Year-5 EBITDA | E11: NPV | F11: IRR | G11: Payback (yrs)
A12: Pessimistic | B12: =D23 -> 2851200 | C12: =H23 -> 5545042.3 | D12: =H26 -> -303436.38 | E12: =C37 -> -4892237.1 | F12: =C38 -> n/a | G12: =C39 -> > 5 yrs
A13: Base | B13: =D43 -> 3960000 | C13: =H43 -> 7701447.6 | D13: =H46 -> 1830144.6 | E13: =C57 -> 203004.1 | F13: =C58 -> 0.15261855 | G13: =C59 -> 4.0792895
A14: Optimistic | B14: =D63 -> 5227200 | C14: =H63 -> 10165911 | D14: =H66 -> 4061394 | E14: =C77 -> 4633870.4 | F14: =C78 -> 0.53820595 | G14: =C79 -> 2.1306725
A16: Check: scenario Base NPV − model NPV (must be 0) | E16: =ROUND(E13-'16_Appraisal'!C15,2) -> 0
A17: Greatest damage | B17: =IF(E12<E13,"Pessimistic scenario: NPV falls by ₹"&TEXT(E13-E12,"#,##0")&" versus base","Check inputs") -> Pessimistic scenario: NPV falls by ₹5,095,241 versus base
A18: Note: electricity is treated as fixed in scenarios (its small volume-linked part is ignored); the effect is negligible.
A22: Scenario engine: Pessimistic | C22: Year 0 | D22: Year 1 | E22: Year 2 | F22: Year 3 | G22: Year 4 | H22: Year 5
A23: Revenue | C23: 0 | D23: ='07_Revenue_Model'!D11*(1+$B$6)*(1+$C$6) -> 2851200 | E23: ='07_Revenue_Model'!E11*(1+$B$6)*(1+$C$6) -> 3592512 | F23: ='07_Revenue_Model'!F11*(1+$B$6)*(1+$C$6) -> 4400827.2 | G23: ='07_Revenue_Model'!G11*(1+$B$6)*(1+$C$6) -> 5016943 | H23: ='07_Revenue_Model'!H11*(1+$B$6)*(1+$C$6) -> 5545042.3
A24: Variable cost | C24: 0 | D24: ='08_Cost_Model'!D9*(1+$B$6)*(1+$D$6) -> 1254528 | E24: ='08_Cost_Model'!E9*(1+$B$6)*(1+$D$6) -> 1580705.3 | F24: ='08_Cost_Model'!F9*(1+$B$6)*(1+$D$6) -> 1936364 | G24: ='08_Cost_Model'!G9*(1+$B$6)*(1+$D$6) -> 2207454.9 | H24: ='08_Cost_Model'!H9*(1+$B$6)*(1+$D$6) -> 2439818.6
A25: Fixed operating cost | C25: 0 | D25: ='08_Cost_Model'!D21*(1+$E$6) -> 2708838 | E25: ='08_Cost_Model'!E21*(1+$E$6) -> 2873148.3 | F25: ='08_Cost_Model'!F21*(1+$E$6) -> 3047246.6 | G25: ='08_Cost_Model'!G21*(1+$E$6) -> 3224667.2 | H25: ='08_Cost_Model'!H21*(1+$E$6) -> 3408660
A26: EBITDA | C26: 0 | D26: =D23-D24-D25 -> -1112166 | E26: =E23-E24-E25 -> -861341.58 | F26: =F23-F24-F25 -> -582783.32 | G26: =G23-G24-G25 -> -415179.11 | H26: =H23-H24-H25 -> -303436.38
A27: Depreciation | C27: 0 | D27: ='09_Assets_Depreciation'!D20 -> 333550 | E27: ='09_Assets_Depreciation'!E20 -> 333550 | F27: ='09_Assets_Depreciation'!F20 -> 333550 | G27: ='09_Assets_Depreciation'!G20 -> 333550 | H27: ='09_Assets_Depreciation'!H20 -> 313550
A28: EBIT | C28: 0 | D28: =D26-D27 -> -1445716 | E28: =E26-E27 -> -1194891.6 | F28: =F26-F27 -> -916333.32 | G28: =G26-G27 -> -748729.11 | H28: =H26-H27 -> -616986.38
A29: Tax on EBIT | C29: 0 | D29: =MAX(0,D28)*'04_Assumptions'!$C$40 -> 0 | E29: =MAX(0,E28)*'04_Assumptions'!$C$40 -> 0 | F29: =MAX(0,F28)*'04_Assumptions'!$C$40 -> 0 | G29: =MAX(0,G28)*'04_Assumptions'!$C$40 -> 0 | H29: =MAX(0,H28)*'04_Assumptions'!$C$40 -> 0
A30: NOPAT | C30: 0 | D30: =D28-D29 -> -1445716 | E30: =E28-E29 -> -1194891.6 | F30: =F28-F29 -> -916333.32 | G30: =G28-G29 -> -748729.11 | H30: =H28-H29 -> -616986.38
